tests/mediumHard/mediumHard_67.in
15
o
2 B 101 GORN 391 30
2 S 104 AAC 1178 723
10 S 106 FEG 1923 485
8 B 109 GEGS 1521 865
10 S 111 AAC 1919 733
10 C 106
1 S 115 A 708 886
12 B 116 VIDE 1183 661
3 S 117 STRIPE 1934 820
4 B 119 HAHEOD 733 346
3 B 120 GLIN 583 548
4 C 119
3 C 120
6 B 123 DOOR 631 828
10 S 125 AA 1309 521
10 C 111
5 B 127 AAIE 1201 438
14 S 128 AAIE 1174 937
8 C 109
0 B 132 CAE 1943 452
4 B 133 CAE 1989 979
12 C 116
12 S 135 A 1810 661
8 S 136 GORN 425 498
10 S 137 THRONE 103 380
2 S 138 AAN 1092 383
14 S 139 GORN 448 306
4 S 140 AAN 1208 469
14 C 128
9 S 142 AAIC 1632 793
13 B 143 GORN 536 177
13 B 144 AAM 1849 386
6 B 145 AAO 1108 902
6 B 146 AAN 1427 495
10 S 147 FEG 264 259
3 S 148 AAIC 389 422
1 S 149 HAHEOD 425 885
11 B 150 AAM 1226 121
11 S 151 AAIE 446 78
13 S 152 GORN 320 190
11 B 153 STRIPE 559 465
6 C 145
10 B 155 BDD 1679 161
5 C 127
0 C 132
0 C 132
13 C 144
3 C 148
5 C 127
0 B 162 AAM 212 756
12 C 116
9 B 165 AAM 312 744
6 S 166 CAE 764 913
6 B 167 GLIN 490 234
9 B 168 HAHEOD 443 207
13 C 144
11 S 170 AAM 784 769
10 B 171 AAIC 1069 593
13 S 172 AAN 1254 934
12 S 173 CONC 1389 743
8 S 174 STRA 797 256
4 C 133
13 B 176 GORN 819 35
1 S 177 DOOR 1958 71
14 S 178 FEG 1655 301
8 C 109
6 B 180 AAM 792 41
7 B 181 DOOR 775 614
5 B 182 GEGS 1217 976
7 C 181
11 C 153
12 B 185 CAE 461 124
13 C 176
8 B 187 BDD 1439 682
7 C 181
6 S 189 VIDE 182 103
8 C 174
14 S 191 STRIPE 1590 768
9 B 192 GLIN 1395 645
10 S 193 CONC 1034 955
1 C 177
12 S 195 GORN 229 25
8 B 196 AAN 1765 142
9 S 197 AAIC 449 615
13 S 198 AAO 487 434
9 S 199 GORN 201 18
3 S 200 STRIPE 154 549
4 S 201 GLIN 1254 658
5 C 182
6 B 203 GORN 1000 702
5 C 127
13 S 205 AAO 1914 783
11 B 206 GEGS 1250 188
8 S 207 DOOR 755 982
3 B 208 VIDE 1444 634
2 S 209 CONC 404 481
11 C 170
7 B 211 THRONE 656 266
14 C 139
11 B 213 CONC 1177 721
3 C 117
5 S 215 AAID 1599 660
3 B 216 HAHEOD 1814 908
1 S 217 AAO 815 602
12 C 173
1 S 219 AAM 1330 507
2 C 104
11 S 221 AAN 297 588
10 S 222 GORN 474 855
12 S 223 AAO 856 845
0 C 132
11 B 225 GLIN 1134 390
3 C 208
7 B 227 AAC 1923 445
4 S 228 A 278 566
5 C 182
4 C 228
5 B 231 BDD 1218 246
3 B 232 HAHEOD 281 496
11 B 233 HAHEOD 1550 992
4 C 133
1 B 235 STRIPE 456 801
8 B 236 AAIN 633 830
4 S 237 VIDE 579 168
9 B 238 THRONE 664 561
3 C 200
5 B 240 AAN 1132 308
2 B 241 CAE 1219 920
11 S 242 GLIN 513 283
7 S 243 AAID 738 392
8 B 244 STRIPE 1158 760
3 C 117
1 B 246 STRIPE 1864 550
9 C 168
1 C 246
5 S 249 AA 923 441
2 C 104
3 C 148
12 B 252 AAC 1446 767
11 C 170
0 C 132
1 B 255 STRA 1407 225
5 B 256 AAIE 422 323
7 B 257 GORN 1959 578
0 S 258 AAIC 565 422
2 S 259 AA 1178 24
6 B 260 CAE 1820 590
1 S 261 HAHEOD 785 746
4 B 262 AAIE 815 387
5 B 263 CAE 364 354
13 B 264 A 1057 842
1 C 255
11 C 150
2 B 267 STRA 977 516
7 B 268 AAC 594 439
8 C 174
6 B 270 AAM 649 742
12 S 271 STRA 1570 344
2 B 272 AA 1076 532
11 B 273 AAIC 861 138
0 B 274 CONC 429 820
8 C 207
5 B 276 AAIE 886 301
13 C 143
8 B 278 AAIE 402 764
9 C 199
12 S 280 STRA 564 424
2 B 281 THRONE 176 766
12 S 282 A 910 54
2 B 283 AAID 880 591
5 B 284 AAN 521 941
1 S 285 CONC 142 803
11 B 286 STRIPE 1308 433
3 S 287 AAO 682 935
2 B 288 AAIN 963 624
1 B 289 AAM 447 202
2 C 267
11 B 291 DOOR 270 471
10 S 292 AAIE 709 97
2 S 293 CAE 1096 36
8 B 294 AAIN 162 371
4 S 295 GORN 1914 112
2 C 104
14 B 297 VIDE 557 405
0 C 132
4 B 299 CAE 929 76
7 S 300 GEGS 1570 493
11 C 206
0 C 258
14 S 303 CONC 156 603
0 C 258
1 S 305 THRONE 1916 459
2 C 293
2 S 307 AAM 333 346
4 B 308 CAE 564 623
8 C 294
2 S 310 AAIE 749 711
6 S 311 STRIPE 1157 173
13 S 312 STRIPE 1023 80
8 S 313 BDD 204 829
5 C 249
8 S 315 CAE 1826 962
14 S 316 AA 290 776
12 C 185
4 C 308
12 B 319 AAIC 1469 133
13 B 320 BDD 706 839
6 B 321 AAC 243 889
10 B 322 AAN 716 703
4 C 201
11 C 221
9 B 325 VIDE 1662 591
5 S 326 HAHEOD 694 239
11 C 273
12 C 173
1 C 235
9 S 330 BDD 1894 238
5 B 331 GLIN 970 545
14 C 316
2 B 333 THRONE 1391 429
12 S 334 BDD 1802 627
10 C 322
11 C 153
5 C 240
7 S 338 STRA 1665 309
12 C 271
13 S 340 AAO 228 788
6 B 341 GLIN 1803 282
11 S 342 AA 1701 883
1 S 343 GLIN 1812 218
1 C 115
2 S 345 FEG 1930 704
13 C 340
6 C 166
12 B 348 GLIN 1142 806
10 S 349 STRIPE 1198 662
13 B 350 AAM 244 212
5 B 351 STRIPE 1576 93
7 S 352 A 1614 420
5 S 353 AAO 1867 453
5 S 354 AAID 1819 833
9 B 355 A 884 244
3 S 356 AAC 398 588
3 B 357 AA 294 53
8 S 358 AAIC 1282 988
6 C 260
5 B 360 BDD 1358 881
10 C 171
7 B 362 CONC 1814 412
6 B 363 HAHEOD 1050 618
8 B 364 CAE 183 196
7 B 365 STRA 610 14
9 C 197
8 S 367 HAHEOD 1767 986
12 C 348
0 B 369 THRONE 403 152
2 C 345
7 S 371 STRA 1479 77
13 C 320
5 B 373 FEG 515 988
10 S 374 CONC 297 162
7 C 365
14 B 376 DOOR 1543 376
3 S 377 THRONE 1751 514
12 C 116
13 B 379 GLIN 1712 125
4 C 262
0 S 381 THRONE 1370 259
11 S 382 AAO 624 510
0 B 383 VIDE 955 912
3 C 216
14 S 385 AAIC 421 739
5 C 182
11 B 387 AA 344 442
5 S 388 AAID 553 804
0 C 383
4 S 390 GEGS 1656 529
3 S 391 STRIPE 868 256
6 S 392 GEGS 1392 143
0 B 393 HAHEOD 251 439
3 S 394 GEGS 1220 391
7 S 395 AAN 358 158
2 B 396 AAN 1423 902
13 S 397 THRONE 1534 972
9 S 398 GORN 148 653
14 C 178
7 C 300
6 B 401 A 1225 991
1 C 217
6 B 403 AAIC 572 930
6 S 404 VIDE 557 733
8 C 358
9 B 406 AAM 1112 292
8 B 407 AAID 1149 821
10 C 292
9 C 330
0 C 381
3 C 117
0 B 412 VIDE 1775 944
14 S 413 AAN 1989 30
6 B 414 AAID 480 342
3 S 415 CAE 1903 692
2 C 101
14 B 417 GORN 1852 286
2 B 418 DOOR 1534 129
6 S 419 STRIPE 1476 244
2 C 267
0 C 383
4 C 308
1 S 423 THRONE 239 695
14 B 424 GEGS 819 590
11 C 286
7 C 300
10 C 322
5 B 428 GORN 1021 729
1 S 429 A 1096 63
10 C 125
6 B 431 AAIE 1116 695
12 B 432 VIDE 1057 488
11 C 291
14 B 434 DOOR 1782 945
4 S 435 GEGS 1504 949
10 C 292
3 C 415
3 B 438 AAIE 497 902
2 S 439 FEG 1471 561
11 B 440 STRIPE 1903 210
10 B 441 STRA 497 204
11 S 442 AAIE 446 813
7 S 443 CAE 907 139
9 C 165
6 B 445 GORN 1488 965
4 C 228
3 B 447 HAHEOD 126 498
13 B 448 VIDE 1919 75
11 S 449 AAIE 1441 991
3 S 450 CONC 520 765
8 C 278
8 S 452 BDD 460 976
1 B 453 AAID 399 491
6 S 454 AAIE 310 847
10 B 455 CAE 1839 680
5 B 456 THRONE 1822 452
13 B 457 BDD 1772 958
4 C 299
10 C 171
9 C 238
10 B 461 BDD 239 157
0 S 462 VIDE 1104 853
0 C 369
0 B 464 CAE 1040 338
8 S 465 GLIN 304 883
0 S 466 CAE 1466 971
13 S 467 GORN 1126 383
14 C 434
9 B 469 AAID 413 843
12 B 470 HAHEOD 763 85
1 B 471 AAO 1190 167
11 C 286
9 S 473 GLIN 1221 582
6 B 474 AA 1917 994
4 B 475 AAM 415 57
8 C 136
10 S 477 A 409 821
4 C 299
7 B 479 GORN 1323 277
0 B 480 AAID 1230 781
12 C 282
3 B 482 AAO 932 823
1 B 483 AAID 1135 833
11 S 484 A 1472 198
10 B 485 GORN 578 353
7 B 486 BDD 1120 74
4 S 487 FEG 419 809
12 B 488 AAC 903 826
1 C 219
4 B 490 BDD 1978 358
1 C 343
3 C 232
12 C 271
10 B 494 AAN 1464 24
0 C 369
6 C 123
8 C 294
3 B 498 CONC 600 175
6 C 403
10 C 485
9 C 406
8 S 502 FEG 626 803
6 S 503 AA 1626 710
2 S 504 GORN 1871 520
11 C 151
14 B 506 AAO 1895 489
2 S 507 STRA 1059 582
7 S 508 AAN 547 239
6 S 509 FEG 578 433
10 C 193
5 S 511 GORN 1756 261
0 C 162
5 B 513 AAO 1542 453
4 B 514 CAE 1458 501
9 C 192
6 S 516 GLIN 356 250
7 S 517 FEG 1874 528
4 S 518 CONC 1099 78
1 S 519 AAIN 1719 101
8 C 196
3 S 521 AAIC 1935 790
9 B 522 BDD 150 41
7 S 523 GORN 1259 20
12 B 524 GORN 1730 46
10 C 322
9 C 330
8 C 187
5 S 528 A 256 536
8 C 313
3 S 530 FEG 1545 70
0 S 531 CONC 1837 916
9 B 532 GORN 284 721
9 S 533 GORN 420 112
6 C 260
12 B 535 GEGS 199 567
14 B 536 AAIN 277 647
9 C 197
10 C 292
1 S 539 HAHEOD 1984 547
5 C 326
6 B 541 GEGS 1949 431
9 C 398
2 C 267
11 S 544 BDD 1553 990
5 C 513
10 S 546 HAHEOD 802 116
14 S 547 DOOR 1174 23
4 C 262
11 C 150
7 S 550 GLIN 1298 328
9 S 551 AAM 305 805
7 C 352
7 S 553 VIDE 246 430
0 B 554 DOOR 808 831
6 S 555 GEGS 1300 19
7 S 556 DOOR 1738 638
0 S 557 GORN 1598 492
6 S 558 AAN 1643 554
7 C 443
0 C 383
5 B 561 AAIC 1821 520
7 C 352
13 C 467
3 B 564 BDD 661 216
0 C 132
14 B 566 A 653 277
8 C 136
6 B 568 FEG 1994 691
6 C 445
7 B 570 AAIC 1606 971
13 B 571 STRIPE 1588 109
2 B 572 AAO 233 551
11 S 573 AAID 1827 696
9 S 574 AAID 1223 563
12 B 575 AAIC 140 960
5 S 576 GORN 402 23
3 S 577 STRIPE 998 84
12 B 578 FEG 1353 83
11 B 579 GLIN 935 440
