tests/mediumHard/mediumHard_68.in
15
o
10 S 101 BDD 105 183
2 B 103 CAE 1417 80
9 B 104 VIDE 1718 308
6 B 105 AAO 1971 775
14 B 107 STRA 1727 851
7 B 108 AAM 228 125
1 S 109 THRONE 526 828
5 B 110 HAHEOD 1708 113
7 B 111 STRA 111 11
9 S 112 AAIN 580 933
10 B 113 FEG 840 889
11 S 114 FEG 841 150
2 C 103
12 B 117 GLIN 1989 252
4 B 118 GLIN 1746 836
6 S 119 A 767 732
6 C 105
2 B 121 AAO 1350 413
12 C 117
6 B 123 THRONE 1418 923
7 B 124 STRIPE 539 285
13 S 125 AA 1068 273
11 B 126 STRA 720 102
7 S 127 CAE 907 515
7 C 124
12 S 130 AAM 1764 606
7 B 131 FEG 1761 474
11 C 126
3 S 133 GEGS 779 90
7 C 131
0 B 135 AAN 373 194
5 S 136 DOOR 814 340
4 B 137 AAIN 377 377
9 C 104
12 B 139 AAC 1503 233
14 C 107
13 C 125
0 C 135
7 B 143 DOOR 836 45
13 C 125
12 S 145 THRONE 976 749
0 B 147 THRONE 1124 403
3 B 148 AAIE 945 316
6 S 149 GORN 196 108
1 B 150 CAE 352 325
2 C 103
6 S 152 AAN 365 911
6 S 153 GLIN 1916 562
3 B 154 A 1044 805
13 C 125
3 B 156 GORN 1056 878
12 C 130
6 C 105
9 B 159 AAN 1551 972
7 B 160 GORN 1575 813
6 C 105
8 S 162 AAC 1042 580
11 B 163 AAN 591 783
8 S 164 AAID 754 53
7 C 143
4 C 118
10 S 167 THRONE 426 903
9 B 168 THRONE 1656 286
9 S 169 AA 892 274
1 S 170 HAHEOD 470 802
11 B 171 BDD 1887 851
14 B 172 CONC 1457 717
4 S 173 CAE 1739 936
11 B 174 AAIN 1971 57
8 C 162
14 C 172
8 B 177 STRA 328 57
13 B 178 GLIN 372 610
2 S 179 AAIN 993 550
11 C 126
10 B 181 A 661 578
1 B 182 AAO 756 705
12 S 183 AAN 681 939
4 B 184 CAE 1582 44
6 C 119
12 C 145
10 B 187 GORN 1849 482
9 B 188 AAIE 816 847
9 B 189 AA 1913 528
1 C 150
5 C 136
5 B 192 GLIN 645 756
10 B 193 GORN 1699 814
10 C 113
1 B 195 AAID 976 792
6 C 149
12 B 197 CONC 1501 874
14 C 107
14 C 172
12 S 200 AAIC 474 244
12 S 201 AAID 598 72
1 C 150
4 B 203 STRIPE 569 788
14 C 107
1 B 205 HAHEOD 722 361
6 S 206 STRA 558 846
11 S 207 GEGS 1313 623
11 C 174
13 C 178
14 C 107
12 C 200
8 B 212 AAIE 522 683
7 S 213 AAN 1370 430
13 B 214 AAM 718 875
13 B 215 GORN 837 950
3 S 216 AAN 1912 677
13 C 125
5 B 218 CONC 845 194
6 C 152
7 C 124
2 B 221 THRONE 1026 723
2 B 222 CAE 297 846
1 S 223 GEGS 1701 812
2 B 224 GORN 206 716
1 S 225 AAIE 229 283
12 B 226 AAID 800 980
2 C 103
12 S 228 GORN 608 258
6 B 229 CONC 1330 815
4 C 137
7 B 231 STRA 243 543
3 S 232 AAC 1914 559
10 S 233 THRONE 1832 399
5 S 234 THRONE 1833 910
13 B 235 AA 1246 119
9 B 236 BDD 852 485
3 S 237 AAN 1750 976
3 C 148
7 S 239 AAIN 651 66
3 S 240 GLIN 701 781
10 B 241 AAN 1534 869
9 S 242 GLIN 764 307
2 B 243 THRONE 1697 975
11 B 244 AAO 1305 521
14 S 245 GORN 1524 664
3 S 246 AAID 1421 215
3 C 246
7 C 239
6 B 249 HAHEOD 1472 822
14 B 250 HAHEOD 1238 114
4 C 184
10 C 187
2 C 222
6 B 254 AAM 980 540
10 B 255 STRA 1614 448
3 C 156
12 B 257 AA 1241 739
8 S 258 AAN 502 851
1 B 259 GLIN 523 167
11 C 207
14 C 245
2 S 262 HAHEOD 393 520
13 B 263 AAIN 1081 429
10 B 264 AAID 1013 969
7 C 131
11 C 207
2 S 267 AA 1143 863
0 B 268 DOOR 429 703
11 B 269 AAO 1651 697
8 S 270 DOOR 1800 995
3 C 154
5 B 272 AAN 1930 31
5 B 273 HAHEOD 853 313
3 S 274 CONC 1141 558
6 B 275 CONC 283 872
2 S 276 VIDE 491 128
11 B 277 CONC 1208 617
7 S 278 BDD 1231 367
4 S 279 HAHEOD 983 783
12 S 280 AAC 1343 831
13 C 235
14 C 172
10 B 283 AAN 1080 491
7 B 284 VIDE 524 632
4 S 285 GEGS 1509 449
0 S 286 AAM 1008 609
13 B 287 A 1499 859
2 S 288 HAHEOD 750 744
8 B 289 GLIN 1772 582
12 S 290 AAC 1845 825
11 B 291 AAIE 1358 385
6 B 292 GORN 1784 765
1 S 293 VIDE 1756 293
5 C 110
0 C 147
11 C 291
12 S 297 AAIE 1866 244
4 B 298 BDD 897 906
3 S 299 CAE 213 104
10 S 300 AAN 1419 628
10 S 301 BDD 243 71
7 B 302 AAID 772 516
13 B 303 FEG 1589 235
7 B 304 STRA 1625 567
4 S 305 VIDE 796 495
0 B 306 THRONE 1503 573
1 S 307 AA 1787 773
11 S 308 HAHEOD 1009 680
12 B 309 AA 896 494
2 B 310 DOOR 1880 108
14 S 311 HAHEOD 332 213
13 S 312 AAN 1268 687
13 B 313 AAM 1892 702
7 S 314 AAID 635 180
5 C 136
12 S 316 AA 1839 695
7 C 213
14 S 318 AAO 308 258
4 B 319 AAC 1982 379
8 S 320 AAIN 1798 148
7 B 321 AAID 1050 564
4 B 322 STRA 992 373
13 C 313
11 S 324 THRONE 239 410
6 C 254
8 B 326 GORN 1453 43
5 B 327 BDD 1519 926
12 B 328 CAE 1029 374
6 S 329 AAM 1186 850
9 S 330 AAIN 1282 80
5 S 331 AAC 699 170
14 B 332 FEG 1938 950
10 S 333 VIDE 1235 264
3 S 334 AAIE 1346 218
12 S 335 VIDE 649 487
4 S 336 BDD 1963 990
8 C 320
1 C 225
0 C 286
7 S 340 AAIC 1573 47
0 B 341 STRA 1516 323
0 S 342 A 678 24
1 S 343 HAHEOD 1977 554
13 B 344 AAID 1805 454
9 S 345 VIDE 1700 551
7 B 346 AA 925 119
11 C 291
4 S 348 GLIN 1511 456
14 B 349 THRONE 339 37
1 B 350 AAO 1001 653
13 S 351 A 1587 150
10 B 352 FEG 1327 436
13 C 178
3 B 354 A 565 562
14 S 355 VIDE 1125 787
7 C 284
13 S 357 CONC 1566 876
0 S 358 CONC 828 514
11 B 359 AAO 653 150
9 B 360 FEG 441 338
12 C 183
9 C 159
6 B 363 GEGS 459 741
0 B 364 A 692 270
0 S 365 VIDE 1074 886
3 B 366 THRONE 262 147
13 B 367 DOOR 420 713
8 S 368 GLIN 1627 54
10 S 369 GEGS 397 504
4 S 370 GLIN 654 86
10 S 371 STRIPE 442 379
12 S 372 AAIC 983 515
14 C 318
6 C 275
0 S 375 AAO 1989 177
6 S 376 AAIE 505 176
14 S 377 AAC 726 505
0 S 378 BDD 1979 892
12 B 379 GORN 1082 919
2 B 380 STRIPE 1397 294
6 S 381 AAM 104 997
7 C 111
1 B 383 AAID 1162 966
11 B 384 AAIN 110 41
5 C 272
7 S 386 AAID 1710 338
2 C 262
12 C 228
9 S 389 AAIE 1537 454
7 S 390 CONC 1002 620
6 B 391 HAHEOD 1802 29
14 S 392 BDD 802 922
0 B 393 HAHEOD 759 500
14 C 349
4 S 395 GLIN 1958 945
4 S 396 AAM 985 114
1 S 397 STRIPE 1168 71
14 S 398 GLIN 1722 408
1 C 170
3 B 400 A 104 933
6 C 254
6 B 402 AAN 1426 186
6 C 376
9 S 404 AAIE 1695 99
12 C 201
5 S 406 STRA 1528 243
6 S 407 AAIN 1832 409
13 C 125
1 S 409 AAN 1708 553
10 S 410 CAE 1335 440
4 C 203
1 B 412 AAC 1622 16
7 S 413 VIDE 977 299
7 C 160
12 S 415 GLIN 1310 936
2 S 416 HAHEOD 1286 73
1 B 417 DOOR 803 910
6 B 418 GLIN 1380 282
7 B 419 GEGS 1936 281
14 S 420 AAIE 867 576
8 B 421 GORN 189 632
8 B 422 AAC 443 799
8 B 423 AA 1595 707
12 C 335
2 C 221
10 B 426 STRA 1076 895
13 C 313
0 C 268
8 S 429 THRONE 1509 186
13 B 430 AAIN 380 554
9 B 431 DOOR 186 671
12 S 432 AAIC 1773 831
11 C 174
2 C 276
8 S 435 DOOR 769 179
6 S 436 DOOR 1358 168
4 C 298
7 C 239
9 B 439 AAID 1094 664
8 C 162
8 C 429
13 S 442 CAE 1690 623
13 S 443 CAE 1191 26
12 S 444 AAIC 1959 714
5 B 445 AAC 418 838
14 B 446 AAIN 677 960
13 B 447 FEG 1643 900
7 C 284
0 B 449 GEGS 1717 698
12 B 450 AAIC 1646 598
4 B 451 GLIN 1120 712
11 C 308
8 B 453 GORN 882 602
11 B 454 AAIN 1604 731
14 B 455 AA 1429 153
4 B 456 GEGS 408 418
7 B 457 FEG 1639 345
13 B 458 GLIN 433 582
7 C 346
14 C 392
14 B 461 AAN 1481 698
10 B 462 AAID 270 941
10 B 463 FEG 574 226
4 B 464 AAIN 142 108
12 C 328
1 C 109
7 S 467 AAO 1942 177
4 S 468 AAN 1816 608
8 B 469 AA 605 870
3 C 400
14 S 471 VIDE 349 58
8 B 472 VIDE 425 391
13 C 178
6 B 474 GORN 814 376
11 S 475 FEG 459 435
3 C 274
6 C 254
5 S 478 A 1929 970
8 B 479 AAIE 1100 222
2 B 480 AAIN 763 616
4 B 481 AAIE 1512 810
3 B 482 STRA 1178 818
13 B 483 AAC 683 669
8 B 484 AAIC 1126 356
14 C 332
1 B 486 FEG 164 967
14 S 487 GORN 505 640
3 S 488 STRA 261 595
10 B 489 AAIN 1149 299
3 B 490 GORN 1528 661
10 B 491 FEG 706 535
4 B 492 AAIN 959 692
7 S 493 AAIE 1901 316
12 B 494 GEGS 1107 793
6 C 474
4 C 492
2 B 497 AAIE 459 775
0 C 341
14 B 499 AAC 643 790
8 C 326
6 C 119
14 B 502 CONC 1167 577
5 S 503 GEGS 960 584
12 S 504 STRIPE 1980 813
3 S 505 BDD 993 219
3 B 506 GEGS 346 114
13 B 507 AAIN 238 423
5 S 508 GEGS 1866 340
11 S 509 AAIC 562 269
9 S 510 CAE 1232 839
4 C 279
11 C 324
7 S 513 AAN 503 734
12 S 514 AAC 1929 834
8 C 435
13 C 442
13 B 517 STRIPE 190 543
7 C 108
2 S 519 AA 1449 382
6 S 520 A 1953 872
12 B 521 AAID 1388 311
5 B 522 AAM 1667 151
13 B 523 A 1131 837
5 C 192
7 C 231
2 S 526 GEGS 507 558
8 S 527 STRIPE 105 124
6 B 528 THRONE 257 781
11 C 244
6 C 275
8 C 320
12 B 532 AA 1604 897
9 C 439
2 S 534 AA 999 782
2 S 535 THRONE 979 286
6 S 536 AAIN 1122 24
1 C 350
8 S 538 STRIPE 185 933
14 B 539 GEGS 626 674
3 B 540 AAM 1253 658
1 B 541 AAIC 1273 59
8 B 542 GLIN 955 355
9 S 543 STRIPE 1882 797
10 B 544 AAM 300 776
1 C 109
9 C 188
7 C 127
14 B 548 AA 1581 622
5 B 549 THRONE 1013 699
2 C 497
8 B 551 AAID 858 673
10 S 552 AAIE 1117 959
0 S 553 AAN 590 951
