tests/mediumHard/mediumHard_69.in
15
o
0 S 104 DOOR 1345 689
1 S 105 A 1766 432
0 S 108 AAM 550 796
10 B 109 HAHEOD 367 393
10 C 109
13 S 111 STRIPE 1340 361
13 C 111
5 B 113 BDD 455 847
2 S 114 A 1119 900
5 S 115 BDD 297 576
11 S 117 HAHEOD 1897 725
1 B 118 GORN 1930 710
7 B 119 GLIN 275 709
4 B 120 CONC 851 627
11 C 117
10 S 122 AAC 1653 117
0 S 123 GORN 975 175
6 B 124 FEG 1116 721
3 S 125 HAHEOD 809 672
13 C 111
0 S 128 DOOR 832 718
7 B 129 GLIN 670 200
13 B 131 HAHEOD 544 582
5 B 132 AAIE 769 703
10 B 134 AAIC 1064 264
14 B 135 AA 1185 630
2 B 136 GLIN 1559 614
3 S 137 AAN 721 358
13 B 138 AAIE 1437 823
5 S 139 CAE 222 548
8 B 140 STRA 974 796
1 B 141 FEG 875 100
11 B 142 AAN 1196 402
8 S 143 CONC 859 464
3 B 144 AAC 139 668
11 S 145 AA 888 595
0 S 146 AAO 1855 231
13 C 138
1 B 148 AAIE 1730 648
11 B 149 AAM 1931 362
0 C 128
0 C 104
10 C 122
1 C 141
1 C 105
8 S 155 GLIN 560 494
0 S 156 AAN 878 225
1 S 157 VIDE 1153 209
9 B 158 AAM 168 764
0 S 159 AAM 1327 207
1 S 160 VIDE 1599 159
4 C 120
0 C 104
7 C 119
11 S 164 AAIN 814 617
13 C 138
9 B 166 AAID 1159 430
9 S 167 FEG 1354 531
4 B 168 AAN 1949 212
6 S 169 AAIE 1716 111
7 S 170 VIDE 1488 913
2 C 114
2 B 172 GORN 890 264
14 C 135
12 B 174 AAIE 1695 424
12 C 174
2 C 136
10 S 177 FEG 836 394
3 B 178 FEG 1354 816
2 S 179 CONC 1391 536
9 B 180 DOOR 604 81
13 B 181 BDD 165 103
12 C 174
x
